<?xml version="1.0"?>
<robot xmlns:xacro="http://www.ros.org/wiki/xacro">

    <xacro:macro name="project_perry" params="parent prefix *origin">

        <!-- Constants for robot dimensions -->
        <xacro:property name="mass" value="1"/> <!-- arbitrary value for mass -->
        <xacro:property name="base_width" value="1"/>
        <xacro:property name="base_height" value="0.6"/>
        <xacro:property name="platter_radius" value="0.75"/>
        <xacro:property name="platter_height" value="0.1"/>
        <xacro:property name="width" value="0.1"/> <!-- Square dimensions (widthxwidth) of beams -->
        <xacro:property name="height1" value="2"/> <!-- Link 1 -->
        <xacro:property name="height2" value="1"/> <!-- Link 2 -->
        <xacro:property name="height3" value="1"/> <!-- Link 3 -->
        <xacro:property name="axel_offset" value="0.05"/> <!-- Space btw top of beam and the each joint -->

        <joint name="${prefix}base_joint" type="fixed">
            <xacro:insert_block name="origin"/>
            <parent link="${parent}"/>
            <child link="${prefix}base_link"/>
        </joint>

        <!-- Base Link -->
        <link name="${prefix}base_link">
            <collision>
                <origin xyz="0 0 ${base_height/2}" rpy="0 0 0"/>
                <geometry>
                    <box size="${base_width} ${base_width} ${base_height}"/>
                </geometry>
            </collision>

            <visual>
                <origin xyz="0 0 ${base_height/2}" rpy="0 0 0"/>
                <geometry>
                    <box size="${base_width} ${base_width} ${base_height}"/>
                </geometry>
                <material name="orange"/>
            </visual>

            <inertial>
                <origin xyz="0 0 ${base_height/2}" rpy="0 0 0"/>
                <mass value="${mass}"/>
                <inertia
                        ixx="${mass / 12.0 * (base_width*base_width + base_height*base_height)}" ixy="0.0" ixz="0.0"
                        iyy="${mass / 12.0 * (base_height*base_height + base_width*base_width)}" iyz="0.0"
                        izz="${mass / 12.0 * (base_width*base_width + base_width*base_width)}"/>
            </inertial>
        </link>

        <joint name="${prefix}base_yaw_joint" type="continuous">
            <parent link="${prefix}base_link"/>
            <child link="${prefix}shoulder_link"/>
            <origin xyz="0 0 ${base_height - axel_offset}" rpy="0 0 0"/>
            <axis xyz="0 0 1"/>
            <dynamics damping="0.7"/>
            <limit effort="100" velocity="1.0"/>
        </joint>

        <!-- Middle Link -->
        <link name="${prefix}shoulder_link">
            <collision>
                <origin xyz="0 0 ${platter_height/2 + axel_offset}" rpy="0 0 0"/>
                <geometry>
                    <cylinder radius="${platter_radius}" length="${platter_height}"/>
                </geometry>
            </collision>

            <visual>
                <origin xyz="0 0 ${platter_height/2 + axel_offset}" rpy="0 0 0"/>
                <geometry>
                    <cylinder radius="${platter_radius}" length="${platter_height}"/>
                </geometry>
                <material name="yellow"/>
            </visual>

            <inertial>
                <origin xyz="0 0 ${platter_height/2 - axel_offset}" rpy="0 0 0"/>
                <mass value="${mass}"/>
                <inertia
                        ixx="${mass / 12.0 * (3*platter_radius*platter_radius + platter_height*platter_height)}" ixy="0.0" ixz="0.0"
                        iyy="${mass / 12.0 * (3*platter_radius*platter_radius + platter_height*platter_height)}" iyz="0.0"
                        izz="${mass / 2.0 * platter_radius*platter_radius}"/>
            </inertial>
        </link>

        <joint name="${prefix}base_pitch_joint" type="revolute">
            <parent link="${prefix}shoulder_link"/>
            <child link="${prefix}humerus_link"/>
            <origin xyz="0 0 ${platter_height + axel_offset*2}" rpy="0 0 0"/>
            <axis xyz="0 1 0"/>
            <dynamics damping="0.7"/>
            <limit lower="${-pi/2.0}" upper="${pi/2.0}" effort="100" velocity="1.0"/>
        </joint>

        <!-- Top Link -->
        <link name="${prefix}humerus_link">
            <collision>
                <origin xyz="0 0 ${height3/2 - axel_offset}" rpy="0 0 0"/>
                <geometry>
                    <box size="${width} ${width} ${height3}"/>
                </geometry>
            </collision>

            <visual>
                <origin xyz="0 0 ${height3/2 - axel_offset}" rpy="0 0 0"/>
                <geometry>
                    <box size="${width} ${width} ${height3}"/>
                </geometry>
                <material name="orange"/>
            </visual>

            <inertial>
                <origin xyz="0 0 ${height3/2 - axel_offset}" rpy="0 0 0"/>
                <mass value="${mass}"/>
                <inertia
                        ixx="${mass / 12.0 * (width*width + height3*height3)}" ixy="0.0" ixz="0.0"
                        iyy="${mass / 12.0 * (height3*height3 + width*width)}" iyz="0.0"
                        izz="${mass / 12.0 * (width*width + width*width)}"/>
            </inertial>
        </link>

        <joint name="${prefix}elbow_0_joint" type="revolute">
            <parent link="${prefix}humerus_link"/>
            <child link="${prefix}gripper_link"/>
            <origin xyz="0 0 ${height3}" rpy="0 0 0"/>
            <axis xyz="0 1 0"/>
            <dynamics damping="0.7"/>
            <limit lower="${-3*pi/4.0}" upper="${3*pi/4.0}" effort="100" velocity="1.0"/>
        </joint>

        <!-- Gripper Link -->
        <link name="${prefix}gripper_link">
            <collision>
                <origin xyz="0 0 ${height3/2 - axel_offset}" rpy="0 0 0"/>
                <geometry>
                    <box size="${width} ${width} ${height3}"/>
                </geometry>
            </collision>

            <visual>
                <origin xyz="0 0 ${height3/2 - axel_offset}" rpy="0 0 0"/>
                <geometry>
                    <box size="${width} ${width} ${height3}"/>
                </geometry>
                <material name="orange"/>
            </visual>

            <inertial>
                <origin xyz="0 0 ${height3/2 - axel_offset}" rpy="0 0 0"/>
                <mass value="${mass}"/>
                <inertia
                        ixx="${mass / 12.0 * (width*width + height3*height3)}" ixy="0.0" ixz="0.0"
                        iyy="${mass / 12.0 * (height3*height3 + width*width)}" iyz="0.0"
                        izz="${mass / 12.0 * (width*width + width*width)}"/>
            </inertial>
        </link>

        <joint name="${prefix}gripper" type="fixed">
            <origin xyz="0 0 1" rpy="0 0 0"/>
            <parent link="${prefix}gripper_link"/>
            <child link="${prefix}tool_link"/>
        </joint>

        <!-- Tool Link -->
        <link name="${prefix}tool_link">
        </link>

    </xacro:macro>

</robot>